2017-08-10 16:26:02,156 Exception on /source.gif [GET]
Traceback (most recent call last):
  File "/usr/local/lib/python2.7/site-packages/flask/app.py", line 1817, in wsgi_app
    response = self.full_dispatch_request()
  File "/usr/local/lib/python2.7/site-packages/flask/app.py", line 1477, in full_dispatch_request
    rv = self.handle_user_exception(e)
  File "/usr/local/lib/python2.7/site-packages/flask/app.py", line 1381, in handle_user_exception
    reraise(exc_type, exc_value, tb)
  File "/usr/local/lib/python2.7/site-packages/flask/app.py", line 1475, in full_dispatch_request
    rv = self.dispatch_request()
  File "/usr/local/lib/python2.7/site-packages/flask/app.py", line 1461, in dispatch_request
    return self.view_functions[rule.endpoint](**req.view_args)
  File "/usr/local/lib/python2.7/site-packages/psiturk/experiment.py", line 713, in regularpage
    return render_template(pagename)
  File "/usr/local/lib/python2.7/site-packages/flask/templating.py", line 127, in render_template
    return _render(ctx.app.jinja_env.get_or_select_template(template_name_or_list),
  File "/usr/local/lib/python2.7/site-packages/jinja2/environment.py", line 869, in get_or_select_template
    return self.get_template(template_name_or_list, parent, globals)
  File "/usr/local/lib/python2.7/site-packages/jinja2/environment.py", line 830, in get_template
    return self._load_template(name, self.make_globals(globals))
  File "/usr/local/lib/python2.7/site-packages/jinja2/environment.py", line 804, in _load_template
    template = self.loader.load(self, name, globals)
  File "/usr/local/lib/python2.7/site-packages/jinja2/loaders.py", line 113, in load
    source, filename, uptodate = self.get_source(environment, name)
  File "/usr/local/lib/python2.7/site-packages/flask/templating.py", line 64, in get_source
    raise TemplateNotFound(template)
TemplateNotFound: source.gif
[2017-08-11 16:04:51,689] ERROR in app: Exception on / [GET]
Traceback (most recent call last):
  File "/home/autolab/anaconda2/lib/python2.7/site-packages/flask/app.py", line 1982, in wsgi_app
    response = self.full_dispatch_request()
  File "/home/autolab/anaconda2/lib/python2.7/site-packages/flask/app.py", line 1614, in full_dispatch_request
    rv = self.handle_user_exception(e)
  File "/home/autolab/anaconda2/lib/python2.7/site-packages/flask/app.py", line 1517, in handle_user_exception
    reraise(exc_type, exc_value, tb)
  File "/home/autolab/anaconda2/lib/python2.7/site-packages/flask/app.py", line 1612, in full_dispatch_request
    rv = self.dispatch_request()
  File "/home/autolab/anaconda2/lib/python2.7/site-packages/flask/app.py", line 1598, in dispatch_request
    return self.view_functions[rule.endpoint](**req.view_args)
  File "/home/autolab/anaconda2/lib/python2.7/site-packages/psiturk/user_utils.py", line 20, in new_func
    resp = make_response(func(*args, **kwargs))
  File "/home/autolab/anaconda2/lib/python2.7/site-packages/psiturk/experiment.py", line 180, in index
    return render_template('default.html')
  File "/home/autolab/anaconda2/lib/python2.7/site-packages/flask/templating.py", line 133, in render_template
    return _render(ctx.app.jinja_env.get_or_select_template(template_name_or_list),
  File "/home/autolab/anaconda2/lib/python2.7/site-packages/jinja2/environment.py", line 869, in get_or_select_template
    return self.get_template(template_name_or_list, parent, globals)
  File "/home/autolab/anaconda2/lib/python2.7/site-packages/jinja2/environment.py", line 830, in get_template
    return self._load_template(name, self.make_globals(globals))
  File "/home/autolab/anaconda2/lib/python2.7/site-packages/jinja2/environment.py", line 804, in _load_template
    template = self.loader.load(self, name, globals)
  File "/home/autolab/anaconda2/lib/python2.7/site-packages/jinja2/loaders.py", line 113, in load
    source, filename, uptodate = self.get_source(environment, name)
  File "/home/autolab/anaconda2/lib/python2.7/site-packages/flask/templating.py", line 57, in get_source
    return self._get_source_fast(environment, template)
  File "/home/autolab/anaconda2/lib/python2.7/site-packages/flask/templating.py", line 85, in _get_source_fast
    raise TemplateNotFound(template)
TemplateNotFound: default.html
[2017-08-11 16:09:29,742] ERROR in app: Exception on / [GET]
Traceback (most recent call last):
  File "/home/autolab/anaconda2/lib/python2.7/site-packages/flask/app.py", line 1982, in wsgi_app
    response = self.full_dispatch_request()
  File "/home/autolab/anaconda2/lib/python2.7/site-packages/flask/app.py", line 1614, in full_dispatch_request
    rv = self.handle_user_exception(e)
  File "/home/autolab/anaconda2/lib/python2.7/site-packages/flask/app.py", line 1517, in handle_user_exception
    reraise(exc_type, exc_value, tb)
  File "/home/autolab/anaconda2/lib/python2.7/site-packages/flask/app.py", line 1612, in full_dispatch_request
    rv = self.dispatch_request()
  File "/home/autolab/anaconda2/lib/python2.7/site-packages/flask/app.py", line 1598, in dispatch_request
    return self.view_functions[rule.endpoint](**req.view_args)
  File "/home/autolab/anaconda2/lib/python2.7/site-packages/psiturk/user_utils.py", line 20, in new_func
    resp = make_response(func(*args, **kwargs))
  File "/home/autolab/anaconda2/lib/python2.7/site-packages/psiturk/experiment.py", line 180, in index
    return render_template('default.html')
  File "/home/autolab/anaconda2/lib/python2.7/site-packages/flask/templating.py", line 133, in render_template
    return _render(ctx.app.jinja_env.get_or_select_template(template_name_or_list),
  File "/home/autolab/anaconda2/lib/python2.7/site-packages/jinja2/environment.py", line 869, in get_or_select_template
    return self.get_template(template_name_or_list, parent, globals)
  File "/home/autolab/anaconda2/lib/python2.7/site-packages/jinja2/environment.py", line 830, in get_template
    return self._load_template(name, self.make_globals(globals))
  File "/home/autolab/anaconda2/lib/python2.7/site-packages/jinja2/environment.py", line 804, in _load_template
    template = self.loader.load(self, name, globals)
  File "/home/autolab/anaconda2/lib/python2.7/site-packages/jinja2/loaders.py", line 113, in load
    source, filename, uptodate = self.get_source(environment, name)
  File "/home/autolab/anaconda2/lib/python2.7/site-packages/flask/templating.py", line 57, in get_source
    return self._get_source_fast(environment, template)
  File "/home/autolab/anaconda2/lib/python2.7/site-packages/flask/templating.py", line 85, in _get_source_fast
    raise TemplateNotFound(template)
TemplateNotFound: default.html
[2017-08-11 16:09:31,254] ERROR in app: Exception on / [GET]
Traceback (most recent call last):
  File "/home/autolab/anaconda2/lib/python2.7/site-packages/flask/app.py", line 1982, in wsgi_app
    response = self.full_dispatch_request()
  File "/home/autolab/anaconda2/lib/python2.7/site-packages/flask/app.py", line 1614, in full_dispatch_request
    rv = self.handle_user_exception(e)
  File "/home/autolab/anaconda2/lib/python2.7/site-packages/flask/app.py", line 1517, in handle_user_exception
    reraise(exc_type, exc_value, tb)
  File "/home/autolab/anaconda2/lib/python2.7/site-packages/flask/app.py", line 1612, in full_dispatch_request
    rv = self.dispatch_request()
  File "/home/autolab/anaconda2/lib/python2.7/site-packages/flask/app.py", line 1598, in dispatch_request
    return self.view_functions[rule.endpoint](**req.view_args)
  File "/home/autolab/anaconda2/lib/python2.7/site-packages/psiturk/user_utils.py", line 20, in new_func
    resp = make_response(func(*args, **kwargs))
  File "/home/autolab/anaconda2/lib/python2.7/site-packages/psiturk/experiment.py", line 180, in index
    return render_template('default.html')
  File "/home/autolab/anaconda2/lib/python2.7/site-packages/flask/templating.py", line 133, in render_template
    return _render(ctx.app.jinja_env.get_or_select_template(template_name_or_list),
  File "/home/autolab/anaconda2/lib/python2.7/site-packages/jinja2/environment.py", line 869, in get_or_select_template
    return self.get_template(template_name_or_list, parent, globals)
  File "/home/autolab/anaconda2/lib/python2.7/site-packages/jinja2/environment.py", line 830, in get_template
    return self._load_template(name, self.make_globals(globals))
  File "/home/autolab/anaconda2/lib/python2.7/site-packages/jinja2/environment.py", line 804, in _load_template
    template = self.loader.load(self, name, globals)
  File "/home/autolab/anaconda2/lib/python2.7/site-packages/jinja2/loaders.py", line 113, in load
    source, filename, uptodate = self.get_source(environment, name)
  File "/home/autolab/anaconda2/lib/python2.7/site-packages/flask/templating.py", line 57, in get_source
    return self._get_source_fast(environment, template)
  File "/home/autolab/anaconda2/lib/python2.7/site-packages/flask/templating.py", line 85, in _get_source_fast
    raise TemplateNotFound(template)
TemplateNotFound: default.html
[2017-08-11 16:09:32,395] ERROR in app: Exception on / [GET]
Traceback (most recent call last):
  File "/home/autolab/anaconda2/lib/python2.7/site-packages/flask/app.py", line 1982, in wsgi_app
    response = self.full_dispatch_request()
  File "/home/autolab/anaconda2/lib/python2.7/site-packages/flask/app.py", line 1614, in full_dispatch_request
    rv = self.handle_user_exception(e)
  File "/home/autolab/anaconda2/lib/python2.7/site-packages/flask/app.py", line 1517, in handle_user_exception
    reraise(exc_type, exc_value, tb)
  File "/home/autolab/anaconda2/lib/python2.7/site-packages/flask/app.py", line 1612, in full_dispatch_request
    rv = self.dispatch_request()
  File "/home/autolab/anaconda2/lib/python2.7/site-packages/flask/app.py", line 1598, in dispatch_request
    return self.view_functions[rule.endpoint](**req.view_args)
  File "/home/autolab/anaconda2/lib/python2.7/site-packages/psiturk/user_utils.py", line 20, in new_func
    resp = make_response(func(*args, **kwargs))
  File "/home/autolab/anaconda2/lib/python2.7/site-packages/psiturk/experiment.py", line 180, in index
    return render_template('default.html')
  File "/home/autolab/anaconda2/lib/python2.7/site-packages/flask/templating.py", line 133, in render_template
    return _render(ctx.app.jinja_env.get_or_select_template(template_name_or_list),
  File "/home/autolab/anaconda2/lib/python2.7/site-packages/jinja2/environment.py", line 869, in get_or_select_template
    return self.get_template(template_name_or_list, parent, globals)
  File "/home/autolab/anaconda2/lib/python2.7/site-packages/jinja2/environment.py", line 830, in get_template
    return self._load_template(name, self.make_globals(globals))
  File "/home/autolab/anaconda2/lib/python2.7/site-packages/jinja2/environment.py", line 804, in _load_template
    template = self.loader.load(self, name, globals)
  File "/home/autolab/anaconda2/lib/python2.7/site-packages/jinja2/loaders.py", line 113, in load
    source, filename, uptodate = self.get_source(environment, name)
  File "/home/autolab/anaconda2/lib/python2.7/site-packages/flask/templating.py", line 57, in get_source
    return self._get_source_fast(environment, template)
  File "/home/autolab/anaconda2/lib/python2.7/site-packages/flask/templating.py", line 85, in _get_source_fast
    raise TemplateNotFound(template)
TemplateNotFound: default.html
[2017-08-11 16:09:33,409] ERROR in app: Exception on / [GET]
Traceback (most recent call last):
  File "/home/autolab/anaconda2/lib/python2.7/site-packages/flask/app.py", line 1982, in wsgi_app
    response = self.full_dispatch_request()
  File "/home/autolab/anaconda2/lib/python2.7/site-packages/flask/app.py", line 1614, in full_dispatch_request
    rv = self.handle_user_exception(e)
  File "/home/autolab/anaconda2/lib/python2.7/site-packages/flask/app.py", line 1517, in handle_user_exception
    reraise(exc_type, exc_value, tb)
  File "/home/autolab/anaconda2/lib/python2.7/site-packages/flask/app.py", line 1612, in full_dispatch_request
    rv = self.dispatch_request()
  File "/home/autolab/anaconda2/lib/python2.7/site-packages/flask/app.py", line 1598, in dispatch_request
    return self.view_functions[rule.endpoint](**req.view_args)
  File "/home/autolab/anaconda2/lib/python2.7/site-packages/psiturk/user_utils.py", line 20, in new_func
    resp = make_response(func(*args, **kwargs))
  File "/home/autolab/anaconda2/lib/python2.7/site-packages/psiturk/experiment.py", line 180, in index
    return render_template('default.html')
  File "/home/autolab/anaconda2/lib/python2.7/site-packages/flask/templating.py", line 133, in render_template
    return _render(ctx.app.jinja_env.get_or_select_template(template_name_or_list),
  File "/home/autolab/anaconda2/lib/python2.7/site-packages/jinja2/environment.py", line 869, in get_or_select_template
    return self.get_template(template_name_or_list, parent, globals)
  File "/home/autolab/anaconda2/lib/python2.7/site-packages/jinja2/environment.py", line 830, in get_template
    return self._load_template(name, self.make_globals(globals))
  File "/home/autolab/anaconda2/lib/python2.7/site-packages/jinja2/environment.py", line 804, in _load_template
    template = self.loader.load(self, name, globals)
  File "/home/autolab/anaconda2/lib/python2.7/site-packages/jinja2/loaders.py", line 113, in load
    source, filename, uptodate = self.get_source(environment, name)
  File "/home/autolab/anaconda2/lib/python2.7/site-packages/flask/templating.py", line 57, in get_source
    return self._get_source_fast(environment, template)
  File "/home/autolab/anaconda2/lib/python2.7/site-packages/flask/templating.py", line 85, in _get_source_fast
    raise TemplateNotFound(template)
TemplateNotFound: default.html
[2017-08-11 16:10:58,339] ERROR in app: Exception on / [GET]
Traceback (most recent call last):
  File "/home/autolab/anaconda2/lib/python2.7/site-packages/flask/app.py", line 1982, in wsgi_app
    response = self.full_dispatch_request()
  File "/home/autolab/anaconda2/lib/python2.7/site-packages/flask/app.py", line 1614, in full_dispatch_request
    rv = self.handle_user_exception(e)
  File "/home/autolab/anaconda2/lib/python2.7/site-packages/flask/app.py", line 1517, in handle_user_exception
    reraise(exc_type, exc_value, tb)
  File "/home/autolab/anaconda2/lib/python2.7/site-packages/flask/app.py", line 1612, in full_dispatch_request
    rv = self.dispatch_request()
  File "/home/autolab/anaconda2/lib/python2.7/site-packages/flask/app.py", line 1598, in dispatch_request
    return self.view_functions[rule.endpoint](**req.view_args)
  File "/home/autolab/anaconda2/lib/python2.7/site-packages/psiturk/user_utils.py", line 20, in new_func
    resp = make_response(func(*args, **kwargs))
  File "/home/autolab/anaconda2/lib/python2.7/site-packages/psiturk/experiment.py", line 180, in index
    return render_template('default.html')
  File "/home/autolab/anaconda2/lib/python2.7/site-packages/flask/templating.py", line 133, in render_template
    return _render(ctx.app.jinja_env.get_or_select_template(template_name_or_list),
  File "/home/autolab/anaconda2/lib/python2.7/site-packages/jinja2/environment.py", line 869, in get_or_select_template
    return self.get_template(template_name_or_list, parent, globals)
  File "/home/autolab/anaconda2/lib/python2.7/site-packages/jinja2/environment.py", line 830, in get_template
    return self._load_template(name, self.make_globals(globals))
  File "/home/autolab/anaconda2/lib/python2.7/site-packages/jinja2/environment.py", line 804, in _load_template
    template = self.loader.load(self, name, globals)
  File "/home/autolab/anaconda2/lib/python2.7/site-packages/jinja2/loaders.py", line 113, in load
    source, filename, uptodate = self.get_source(environment, name)
  File "/home/autolab/anaconda2/lib/python2.7/site-packages/flask/templating.py", line 57, in get_source
    return self._get_source_fast(environment, template)
  File "/home/autolab/anaconda2/lib/python2.7/site-packages/flask/templating.py", line 85, in _get_source_fast
    raise TemplateNotFound(template)
TemplateNotFound: default.html
[2017-08-11 16:11:14,727] ERROR in app: Exception on / [GET]
Traceback (most recent call last):
  File "/home/autolab/anaconda2/lib/python2.7/site-packages/flask/app.py", line 1982, in wsgi_app
    response = self.full_dispatch_request()
  File "/home/autolab/anaconda2/lib/python2.7/site-packages/flask/app.py", line 1614, in full_dispatch_request
    rv = self.handle_user_exception(e)
  File "/home/autolab/anaconda2/lib/python2.7/site-packages/flask/app.py", line 1517, in handle_user_exception
    reraise(exc_type, exc_value, tb)
  File "/home/autolab/anaconda2/lib/python2.7/site-packages/flask/app.py", line 1612, in full_dispatch_request
    rv = self.dispatch_request()
  File "/home/autolab/anaconda2/lib/python2.7/site-packages/flask/app.py", line 1598, in dispatch_request
    return self.view_functions[rule.endpoint](**req.view_args)
  File "/home/autolab/anaconda2/lib/python2.7/site-packages/psiturk/user_utils.py", line 20, in new_func
    resp = make_response(func(*args, **kwargs))
  File "/home/autolab/anaconda2/lib/python2.7/site-packages/psiturk/experiment.py", line 180, in index
    return render_template('default.html')
  File "/home/autolab/anaconda2/lib/python2.7/site-packages/flask/templating.py", line 133, in render_template
    return _render(ctx.app.jinja_env.get_or_select_template(template_name_or_list),
  File "/home/autolab/anaconda2/lib/python2.7/site-packages/jinja2/environment.py", line 869, in get_or_select_template
    return self.get_template(template_name_or_list, parent, globals)
  File "/home/autolab/anaconda2/lib/python2.7/site-packages/jinja2/environment.py", line 830, in get_template
    return self._load_template(name, self.make_globals(globals))
  File "/home/autolab/anaconda2/lib/python2.7/site-packages/jinja2/environment.py", line 804, in _load_template
    template = self.loader.load(self, name, globals)
  File "/home/autolab/anaconda2/lib/python2.7/site-packages/jinja2/loaders.py", line 113, in load
    source, filename, uptodate = self.get_source(environment, name)
  File "/home/autolab/anaconda2/lib/python2.7/site-packages/flask/templating.py", line 57, in get_source
    return self._get_source_fast(environment, template)
  File "/home/autolab/anaconda2/lib/python2.7/site-packages/flask/templating.py", line 85, in _get_source_fast
    raise TemplateNotFound(template)
TemplateNotFound: default.html
[2017-08-11 16:12:29,015] ERROR in app: Exception on / [GET]
Traceback (most recent call last):
  File "/home/autolab/anaconda2/lib/python2.7/site-packages/flask/app.py", line 1982, in wsgi_app
    response = self.full_dispatch_request()
  File "/home/autolab/anaconda2/lib/python2.7/site-packages/flask/app.py", line 1614, in full_dispatch_request
    rv = self.handle_user_exception(e)
  File "/home/autolab/anaconda2/lib/python2.7/site-packages/flask/app.py", line 1517, in handle_user_exception
    reraise(exc_type, exc_value, tb)
  File "/home/autolab/anaconda2/lib/python2.7/site-packages/flask/app.py", line 1612, in full_dispatch_request
    rv = self.dispatch_request()
  File "/home/autolab/anaconda2/lib/python2.7/site-packages/flask/app.py", line 1598, in dispatch_request
    return self.view_functions[rule.endpoint](**req.view_args)
  File "/home/autolab/anaconda2/lib/python2.7/site-packages/psiturk/user_utils.py", line 20, in new_func
    resp = make_response(func(*args, **kwargs))
  File "/home/autolab/anaconda2/lib/python2.7/site-packages/psiturk/experiment.py", line 180, in index
    return render_template('default.html')
  File "/home/autolab/anaconda2/lib/python2.7/site-packages/flask/templating.py", line 133, in render_template
    return _render(ctx.app.jinja_env.get_or_select_template(template_name_or_list),
  File "/home/autolab/anaconda2/lib/python2.7/site-packages/jinja2/environment.py", line 869, in get_or_select_template
    return self.get_template(template_name_or_list, parent, globals)
  File "/home/autolab/anaconda2/lib/python2.7/site-packages/jinja2/environment.py", line 830, in get_template
    return self._load_template(name, self.make_globals(globals))
  File "/home/autolab/anaconda2/lib/python2.7/site-packages/jinja2/environment.py", line 804, in _load_template
    template = self.loader.load(self, name, globals)
  File "/home/autolab/anaconda2/lib/python2.7/site-packages/jinja2/loaders.py", line 113, in load
    source, filename, uptodate = self.get_source(environment, name)
  File "/home/autolab/anaconda2/lib/python2.7/site-packages/flask/templating.py", line 57, in get_source
    return self._get_source_fast(environment, template)
  File "/home/autolab/anaconda2/lib/python2.7/site-packages/flask/templating.py", line 85, in _get_source_fast
    raise TemplateNotFound(template)
TemplateNotFound: default.html
[2017-08-11 16:12:30,431] ERROR in app: Exception on / [GET]
Traceback (most recent call last):
  File "/home/autolab/anaconda2/lib/python2.7/site-packages/flask/app.py", line 1982, in wsgi_app
    response = self.full_dispatch_request()
  File "/home/autolab/anaconda2/lib/python2.7/site-packages/flask/app.py", line 1614, in full_dispatch_request
    rv = self.handle_user_exception(e)
  File "/home/autolab/anaconda2/lib/python2.7/site-packages/flask/app.py", line 1517, in handle_user_exception
    reraise(exc_type, exc_value, tb)
  File "/home/autolab/anaconda2/lib/python2.7/site-packages/flask/app.py", line 1612, in full_dispatch_request
    rv = self.dispatch_request()
  File "/home/autolab/anaconda2/lib/python2.7/site-packages/flask/app.py", line 1598, in dispatch_request
    return self.view_functions[rule.endpoint](**req.view_args)
  File "/home/autolab/anaconda2/lib/python2.7/site-packages/psiturk/user_utils.py", line 20, in new_func
    resp = make_response(func(*args, **kwargs))
  File "/home/autolab/anaconda2/lib/python2.7/site-packages/psiturk/experiment.py", line 180, in index
    return render_template('default.html')
  File "/home/autolab/anaconda2/lib/python2.7/site-packages/flask/templating.py", line 133, in render_template
    return _render(ctx.app.jinja_env.get_or_select_template(template_name_or_list),
  File "/home/autolab/anaconda2/lib/python2.7/site-packages/jinja2/environment.py", line 869, in get_or_select_template
    return self.get_template(template_name_or_list, parent, globals)
  File "/home/autolab/anaconda2/lib/python2.7/site-packages/jinja2/environment.py", line 830, in get_template
    return self._load_template(name, self.make_globals(globals))
  File "/home/autolab/anaconda2/lib/python2.7/site-packages/jinja2/environment.py", line 804, in _load_template
    template = self.loader.load(self, name, globals)
  File "/home/autolab/anaconda2/lib/python2.7/site-packages/jinja2/loaders.py", line 113, in load
    source, filename, uptodate = self.get_source(environment, name)
  File "/home/autolab/anaconda2/lib/python2.7/site-packages/flask/templating.py", line 57, in get_source
    return self._get_source_fast(environment, template)
  File "/home/autolab/anaconda2/lib/python2.7/site-packages/flask/templating.py", line 85, in _get_source_fast
    raise TemplateNotFound(template)
TemplateNotFound: default.html
[2017-08-11 16:12:31,503] ERROR in app: Exception on / [GET]
Traceback (most recent call last):
  File "/home/autolab/anaconda2/lib/python2.7/site-packages/flask/app.py", line 1982, in wsgi_app
    response = self.full_dispatch_request()
  File "/home/autolab/anaconda2/lib/python2.7/site-packages/flask/app.py", line 1614, in full_dispatch_request
    rv = self.handle_user_exception(e)
  File "/home/autolab/anaconda2/lib/python2.7/site-packages/flask/app.py", line 1517, in handle_user_exception
    reraise(exc_type, exc_value, tb)
  File "/home/autolab/anaconda2/lib/python2.7/site-packages/flask/app.py", line 1612, in full_dispatch_request
    rv = self.dispatch_request()
  File "/home/autolab/anaconda2/lib/python2.7/site-packages/flask/app.py", line 1598, in dispatch_request
    return self.view_functions[rule.endpoint](**req.view_args)
  File "/home/autolab/anaconda2/lib/python2.7/site-packages/psiturk/user_utils.py", line 20, in new_func
    resp = make_response(func(*args, **kwargs))
  File "/home/autolab/anaconda2/lib/python2.7/site-packages/psiturk/experiment.py", line 180, in index
    return render_template('default.html')
  File "/home/autolab/anaconda2/lib/python2.7/site-packages/flask/templating.py", line 133, in render_template
    return _render(ctx.app.jinja_env.get_or_select_template(template_name_or_list),
  File "/home/autolab/anaconda2/lib/python2.7/site-packages/jinja2/environment.py", line 869, in get_or_select_template
    return self.get_template(template_name_or_list, parent, globals)
  File "/home/autolab/anaconda2/lib/python2.7/site-packages/jinja2/environment.py", line 830, in get_template
    return self._load_template(name, self.make_globals(globals))
  File "/home/autolab/anaconda2/lib/python2.7/site-packages/jinja2/environment.py", line 804, in _load_template
    template = self.loader.load(self, name, globals)
  File "/home/autolab/anaconda2/lib/python2.7/site-packages/jinja2/loaders.py", line 113, in load
    source, filename, uptodate = self.get_source(environment, name)
  File "/home/autolab/anaconda2/lib/python2.7/site-packages/flask/templating.py", line 57, in get_source
    return self._get_source_fast(environment, template)
  File "/home/autolab/anaconda2/lib/python2.7/site-packages/flask/templating.py", line 85, in _get_source_fast
    raise TemplateNotFound(template)
TemplateNotFound: default.html
[2017-08-11 16:12:32,618] ERROR in app: Exception on / [GET]
Traceback (most recent call last):
  File "/home/autolab/anaconda2/lib/python2.7/site-packages/flask/app.py", line 1982, in wsgi_app
    response = self.full_dispatch_request()
  File "/home/autolab/anaconda2/lib/python2.7/site-packages/flask/app.py", line 1614, in full_dispatch_request
    rv = self.handle_user_exception(e)
  File "/home/autolab/anaconda2/lib/python2.7/site-packages/flask/app.py", line 1517, in handle_user_exception
    reraise(exc_type, exc_value, tb)
  File "/home/autolab/anaconda2/lib/python2.7/site-packages/flask/app.py", line 1612, in full_dispatch_request
    rv = self.dispatch_request()
  File "/home/autolab/anaconda2/lib/python2.7/site-packages/flask/app.py", line 1598, in dispatch_request
    return self.view_functions[rule.endpoint](**req.view_args)
  File "/home/autolab/anaconda2/lib/python2.7/site-packages/psiturk/user_utils.py", line 20, in new_func
    resp = make_response(func(*args, **kwargs))
  File "/home/autolab/anaconda2/lib/python2.7/site-packages/psiturk/experiment.py", line 180, in index
    return render_template('default.html')
  File "/home/autolab/anaconda2/lib/python2.7/site-packages/flask/templating.py", line 133, in render_template
    return _render(ctx.app.jinja_env.get_or_select_template(template_name_or_list),
  File "/home/autolab/anaconda2/lib/python2.7/site-packages/jinja2/environment.py", line 869, in get_or_select_template
    return self.get_template(template_name_or_list, parent, globals)
  File "/home/autolab/anaconda2/lib/python2.7/site-packages/jinja2/environment.py", line 830, in get_template
    return self._load_template(name, self.make_globals(globals))
  File "/home/autolab/anaconda2/lib/python2.7/site-packages/jinja2/environment.py", line 804, in _load_template
    template = self.loader.load(self, name, globals)
  File "/home/autolab/anaconda2/lib/python2.7/site-packages/jinja2/loaders.py", line 113, in load
    source, filename, uptodate = self.get_source(environment, name)
  File "/home/autolab/anaconda2/lib/python2.7/site-packages/flask/templating.py", line 57, in get_source
    return self._get_source_fast(environment, template)
  File "/home/autolab/anaconda2/lib/python2.7/site-packages/flask/templating.py", line 85, in _get_source_fast
    raise TemplateNotFound(template)
TemplateNotFound: default.html
[2017-08-11 16:21:41,348] ERROR in app: Exception on / [GET]
Traceback (most recent call last):
  File "/home/autolab/anaconda2/lib/python2.7/site-packages/flask/app.py", line 1982, in wsgi_app
    response = self.full_dispatch_request()
  File "/home/autolab/anaconda2/lib/python2.7/site-packages/flask/app.py", line 1614, in full_dispatch_request
    rv = self.handle_user_exception(e)
  File "/home/autolab/anaconda2/lib/python2.7/site-packages/flask/app.py", line 1517, in handle_user_exception
    reraise(exc_type, exc_value, tb)
  File "/home/autolab/anaconda2/lib/python2.7/site-packages/flask/app.py", line 1612, in full_dispatch_request
    rv = self.dispatch_request()
  File "/home/autolab/anaconda2/lib/python2.7/site-packages/flask/app.py", line 1598, in dispatch_request
    return self.view_functions[rule.endpoint](**req.view_args)
  File "/home/autolab/anaconda2/lib/python2.7/site-packages/psiturk/user_utils.py", line 20, in new_func
    resp = make_response(func(*args, **kwargs))
  File "/home/autolab/anaconda2/lib/python2.7/site-packages/psiturk/experiment.py", line 180, in index
    return render_template('default.html')
  File "/home/autolab/anaconda2/lib/python2.7/site-packages/flask/templating.py", line 133, in render_template
    return _render(ctx.app.jinja_env.get_or_select_template(template_name_or_list),
  File "/home/autolab/anaconda2/lib/python2.7/site-packages/jinja2/environment.py", line 869, in get_or_select_template
    return self.get_template(template_name_or_list, parent, globals)
  File "/home/autolab/anaconda2/lib/python2.7/site-packages/jinja2/environment.py", line 830, in get_template
    return self._load_template(name, self.make_globals(globals))
  File "/home/autolab/anaconda2/lib/python2.7/site-packages/jinja2/environment.py", line 804, in _load_template
    template = self.loader.load(self, name, globals)
  File "/home/autolab/anaconda2/lib/python2.7/site-packages/jinja2/loaders.py", line 113, in load
    source, filename, uptodate = self.get_source(environment, name)
  File "/home/autolab/anaconda2/lib/python2.7/site-packages/flask/templating.py", line 57, in get_source
    return self._get_source_fast(environment, template)
  File "/home/autolab/anaconda2/lib/python2.7/site-packages/flask/templating.py", line 85, in _get_source_fast
    raise TemplateNotFound(template)
TemplateNotFound: default.html
[2017-08-12 06:09:09,204] ERROR in app: Exception on / [GET]
Traceback (most recent call last):
  File "/home/autolab/anaconda2/lib/python2.7/site-packages/flask/app.py", line 1982, in wsgi_app
    response = self.full_dispatch_request()
  File "/home/autolab/anaconda2/lib/python2.7/site-packages/flask/app.py", line 1614, in full_dispatch_request
    rv = self.handle_user_exception(e)
  File "/home/autolab/anaconda2/lib/python2.7/site-packages/flask/app.py", line 1517, in handle_user_exception
    reraise(exc_type, exc_value, tb)
  File "/home/autolab/anaconda2/lib/python2.7/site-packages/flask/app.py", line 1612, in full_dispatch_request
    rv = self.dispatch_request()
  File "/home/autolab/anaconda2/lib/python2.7/site-packages/flask/app.py", line 1598, in dispatch_request
    return self.view_functions[rule.endpoint](**req.view_args)
  File "/home/autolab/anaconda2/lib/python2.7/site-packages/psiturk/user_utils.py", line 20, in new_func
    resp = make_response(func(*args, **kwargs))
  File "/home/autolab/anaconda2/lib/python2.7/site-packages/psiturk/experiment.py", line 180, in index
    return render_template('default.html')
  File "/home/autolab/anaconda2/lib/python2.7/site-packages/flask/templating.py", line 133, in render_template
    return _render(ctx.app.jinja_env.get_or_select_template(template_name_or_list),
  File "/home/autolab/anaconda2/lib/python2.7/site-packages/jinja2/environment.py", line 869, in get_or_select_template
    return self.get_template(template_name_or_list, parent, globals)
  File "/home/autolab/anaconda2/lib/python2.7/site-packages/jinja2/environment.py", line 830, in get_template
    return self._load_template(name, self.make_globals(globals))
  File "/home/autolab/anaconda2/lib/python2.7/site-packages/jinja2/environment.py", line 804, in _load_template
    template = self.loader.load(self, name, globals)
  File "/home/autolab/anaconda2/lib/python2.7/site-packages/jinja2/loaders.py", line 113, in load
    source, filename, uptodate = self.get_source(environment, name)
  File "/home/autolab/anaconda2/lib/python2.7/site-packages/flask/templating.py", line 57, in get_source
    return self._get_source_fast(environment, template)
  File "/home/autolab/anaconda2/lib/python2.7/site-packages/flask/templating.py", line 85, in _get_source_fast
    raise TemplateNotFound(template)
TemplateNotFound: default.html
[2017-08-12 12:07:26,740] ERROR in app: Exception on / [GET]
Traceback (most recent call last):
  File "/home/autolab/anaconda2/lib/python2.7/site-packages/flask/app.py", line 1982, in wsgi_app
    response = self.full_dispatch_request()
  File "/home/autolab/anaconda2/lib/python2.7/site-packages/flask/app.py", line 1614, in full_dispatch_request
    rv = self.handle_user_exception(e)
  File "/home/autolab/anaconda2/lib/python2.7/site-packages/flask/app.py", line 1517, in handle_user_exception
    reraise(exc_type, exc_value, tb)
  File "/home/autolab/anaconda2/lib/python2.7/site-packages/flask/app.py", line 1612, in full_dispatch_request
    rv = self.dispatch_request()
  File "/home/autolab/anaconda2/lib/python2.7/site-packages/flask/app.py", line 1598, in dispatch_request
    return self.view_functions[rule.endpoint](**req.view_args)
  File "/home/autolab/anaconda2/lib/python2.7/site-packages/psiturk/user_utils.py", line 20, in new_func
    resp = make_response(func(*args, **kwargs))
  File "/home/autolab/anaconda2/lib/python2.7/site-packages/psiturk/experiment.py", line 180, in index
    return render_template('default.html')
  File "/home/autolab/anaconda2/lib/python2.7/site-packages/flask/templating.py", line 133, in render_template
    return _render(ctx.app.jinja_env.get_or_select_template(template_name_or_list),
  File "/home/autolab/anaconda2/lib/python2.7/site-packages/jinja2/environment.py", line 869, in get_or_select_template
    return self.get_template(template_name_or_list, parent, globals)
  File "/home/autolab/anaconda2/lib/python2.7/site-packages/jinja2/environment.py", line 830, in get_template
    return self._load_template(name, self.make_globals(globals))
  File "/home/autolab/anaconda2/lib/python2.7/site-packages/jinja2/environment.py", line 804, in _load_template
    template = self.loader.load(self, name, globals)
  File "/home/autolab/anaconda2/lib/python2.7/site-packages/jinja2/loaders.py", line 113, in load
    source, filename, uptodate = self.get_source(environment, name)
  File "/home/autolab/anaconda2/lib/python2.7/site-packages/flask/templating.py", line 57, in get_source
    return self._get_source_fast(environment, template)
  File "/home/autolab/anaconda2/lib/python2.7/site-packages/flask/templating.py", line 85, in _get_source_fast
    raise TemplateNotFound(template)
TemplateNotFound: default.html
[2017-08-12 13:24:33,999] ERROR in app: Exception on / [GET]
Traceback (most recent call last):
  File "/home/autolab/anaconda2/lib/python2.7/site-packages/flask/app.py", line 1982, in wsgi_app
    response = self.full_dispatch_request()
  File "/home/autolab/anaconda2/lib/python2.7/site-packages/flask/app.py", line 1614, in full_dispatch_request
    rv = self.handle_user_exception(e)
  File "/home/autolab/anaconda2/lib/python2.7/site-packages/flask/app.py", line 1517, in handle_user_exception
    reraise(exc_type, exc_value, tb)
  File "/home/autolab/anaconda2/lib/python2.7/site-packages/flask/app.py", line 1612, in full_dispatch_request
    rv = self.dispatch_request()
  File "/home/autolab/anaconda2/lib/python2.7/site-packages/flask/app.py", line 1598, in dispatch_request
    return self.view_functions[rule.endpoint](**req.view_args)
  File "/home/autolab/anaconda2/lib/python2.7/site-packages/psiturk/user_utils.py", line 20, in new_func
    resp = make_response(func(*args, **kwargs))
  File "/home/autolab/anaconda2/lib/python2.7/site-packages/psiturk/experiment.py", line 180, in index
    return render_template('default.html')
  File "/home/autolab/anaconda2/lib/python2.7/site-packages/flask/templating.py", line 133, in render_template
    return _render(ctx.app.jinja_env.get_or_select_template(template_name_or_list),
  File "/home/autolab/anaconda2/lib/python2.7/site-packages/jinja2/environment.py", line 869, in get_or_select_template
    return self.get_template(template_name_or_list, parent, globals)
  File "/home/autolab/anaconda2/lib/python2.7/site-packages/jinja2/environment.py", line 830, in get_template
    return self._load_template(name, self.make_globals(globals))
  File "/home/autolab/anaconda2/lib/python2.7/site-packages/jinja2/environment.py", line 804, in _load_template
    template = self.loader.load(self, name, globals)
  File "/home/autolab/anaconda2/lib/python2.7/site-packages/jinja2/loaders.py", line 113, in load
    source, filename, uptodate = self.get_source(environment, name)
  File "/home/autolab/anaconda2/lib/python2.7/site-packages/flask/templating.py", line 57, in get_source
    return self._get_source_fast(environment, template)
  File "/home/autolab/anaconda2/lib/python2.7/site-packages/flask/templating.py", line 85, in _get_source_fast
    raise TemplateNotFound(template)
TemplateNotFound: default.html
[2017-08-14 00:02:02,946] ERROR in app: Exception on / [GET]
Traceback (most recent call last):
  File "/home/autolab/anaconda2/lib/python2.7/site-packages/flask/app.py", line 1982, in wsgi_app
    response = self.full_dispatch_request()
  File "/home/autolab/anaconda2/lib/python2.7/site-packages/flask/app.py", line 1614, in full_dispatch_request
    rv = self.handle_user_exception(e)
  File "/home/autolab/anaconda2/lib/python2.7/site-packages/flask/app.py", line 1517, in handle_user_exception
    reraise(exc_type, exc_value, tb)
  File "/home/autolab/anaconda2/lib/python2.7/site-packages/flask/app.py", line 1612, in full_dispatch_request
    rv = self.dispatch_request()
  File "/home/autolab/anaconda2/lib/python2.7/site-packages/flask/app.py", line 1598, in dispatch_request
    return self.view_functions[rule.endpoint](**req.view_args)
  File "/home/autolab/anaconda2/lib/python2.7/site-packages/psiturk/user_utils.py", line 20, in new_func
    resp = make_response(func(*args, **kwargs))
  File "/home/autolab/anaconda2/lib/python2.7/site-packages/psiturk/experiment.py", line 180, in index
    return render_template('default.html')
  File "/home/autolab/anaconda2/lib/python2.7/site-packages/flask/templating.py", line 133, in render_template
    return _render(ctx.app.jinja_env.get_or_select_template(template_name_or_list),
  File "/home/autolab/anaconda2/lib/python2.7/site-packages/jinja2/environment.py", line 869, in get_or_select_template
    return self.get_template(template_name_or_list, parent, globals)
  File "/home/autolab/anaconda2/lib/python2.7/site-packages/jinja2/environment.py", line 830, in get_template
    return self._load_template(name, self.make_globals(globals))
  File "/home/autolab/anaconda2/lib/python2.7/site-packages/jinja2/environment.py", line 804, in _load_template
    template = self.loader.load(self, name, globals)
  File "/home/autolab/anaconda2/lib/python2.7/site-packages/jinja2/loaders.py", line 113, in load
    source, filename, uptodate = self.get_source(environment, name)
  File "/home/autolab/anaconda2/lib/python2.7/site-packages/flask/templating.py", line 57, in get_source
    return self._get_source_fast(environment, template)
  File "/home/autolab/anaconda2/lib/python2.7/site-packages/flask/templating.py", line 85, in _get_source_fast
    raise TemplateNotFound(template)
TemplateNotFound: default.html
[2017-08-14 09:14:06 +0000] [18881] [CRITICAL] WORKER TIMEOUT (pid:18886)
[2017-08-14 09:14:06 +0000] [18881] [CRITICAL] WORKER TIMEOUT (pid:18913)
[2018-04-06 18:27:14 -0700] [19509] [ERROR] Invalid address: ('10.0.0.95', 22362)
[2018-04-06 18:27:14 -0700] [19509] [ERROR] Retrying in 1 second.
[2018-04-06 18:27:15 -0700] [19509] [ERROR] Invalid address: ('10.0.0.95', 22362)
[2018-04-06 18:27:15 -0700] [19509] [ERROR] Retrying in 1 second.
[2018-04-06 18:27:16 -0700] [19509] [ERROR] Invalid address: ('10.0.0.95', 22362)
[2018-04-06 18:27:16 -0700] [19509] [ERROR] Retrying in 1 second.
[2018-04-06 18:27:17 -0700] [19509] [ERROR] Invalid address: ('10.0.0.95', 22362)
[2018-04-06 18:27:17 -0700] [19509] [ERROR] Retrying in 1 second.
[2018-04-06 18:27:18 -0700] [19509] [ERROR] Invalid address: ('10.0.0.95', 22362)
[2018-04-06 18:27:18 -0700] [19509] [ERROR] Retrying in 1 second.
[2018-04-06 18:27:19 -0700] [19509] [ERROR] Can't connect to ('10.0.0.95', 22362)
[2018-04-06 18:27:23 -0700] [19536] [ERROR] Invalid address: ('10.0.0.95', 22362)
[2018-04-06 18:27:23 -0700] [19536] [ERROR] Retrying in 1 second.
[2018-04-06 18:27:24 -0700] [19536] [ERROR] Invalid address: ('10.0.0.95', 22362)
[2018-04-06 18:27:24 -0700] [19536] [ERROR] Retrying in 1 second.
[2018-04-06 18:27:25 -0700] [19536] [ERROR] Invalid address: ('10.0.0.95', 22362)
[2018-04-06 18:27:25 -0700] [19536] [ERROR] Retrying in 1 second.
[2018-04-06 18:27:26 -0700] [19536] [ERROR] Invalid address: ('10.0.0.95', 22362)
[2018-04-06 18:27:26 -0700] [19536] [ERROR] Retrying in 1 second.
[2018-04-06 18:27:27 -0700] [19536] [ERROR] Invalid address: ('10.0.0.95', 22362)
[2018-04-06 18:27:27 -0700] [19536] [ERROR] Retrying in 1 second.
[2018-04-06 18:27:28 -0700] [19536] [ERROR] Can't connect to ('10.0.0.95', 22362)
[2018-04-06 18:28:46 -0700] [19578] [ERROR] Invalid address: ('10.0.0.95', 5000)
[2018-04-06 18:28:46 -0700] [19578] [ERROR] Retrying in 1 second.
[2018-04-06 18:28:47 -0700] [19578] [ERROR] Invalid address: ('10.0.0.95', 5000)
[2018-04-06 18:28:47 -0700] [19578] [ERROR] Retrying in 1 second.
[2018-04-06 18:28:48 -0700] [19578] [ERROR] Invalid address: ('10.0.0.95', 5000)
[2018-04-06 18:28:48 -0700] [19578] [ERROR] Retrying in 1 second.
[2018-04-06 18:28:49 -0700] [19578] [ERROR] Invalid address: ('10.0.0.95', 5000)
[2018-04-06 18:28:49 -0700] [19578] [ERROR] Retrying in 1 second.
[2018-04-06 18:28:50 -0700] [19578] [ERROR] Invalid address: ('10.0.0.95', 5000)
[2018-04-06 18:28:50 -0700] [19578] [ERROR] Retrying in 1 second.
[2018-04-06 18:28:51 -0700] [19578] [ERROR] Can't connect to ('10.0.0.95', 5000)
[2018-04-06 18:34:47 -0700] [19641] [ERROR] Invalid address: ('10.0.0.95', 5000)
[2018-04-06 18:34:47 -0700] [19641] [ERROR] Retrying in 1 second.
[2018-04-06 18:34:48 -0700] [19641] [ERROR] Invalid address: ('10.0.0.95', 5000)
[2018-04-06 18:34:48 -0700] [19641] [ERROR] Retrying in 1 second.
[2018-04-06 18:34:49 -0700] [19641] [ERROR] Invalid address: ('10.0.0.95', 5000)
[2018-04-06 18:34:49 -0700] [19641] [ERROR] Retrying in 1 second.
[2018-04-06 18:34:50 -0700] [19641] [ERROR] Invalid address: ('10.0.0.95', 5000)
[2018-04-06 18:34:50 -0700] [19641] [ERROR] Retrying in 1 second.
[2018-04-06 18:34:51 -0700] [19641] [ERROR] Invalid address: ('10.0.0.95', 5000)
[2018-04-06 18:34:51 -0700] [19641] [ERROR] Retrying in 1 second.
[2018-04-06 18:34:52 -0700] [19641] [ERROR] Can't connect to ('10.0.0.95', 5000)
[2018-04-06 18:36:35 -0700] [19676] [ERROR] Invalid address: ('10.0.0.95', 22362)
[2018-04-06 18:36:35 -0700] [19676] [ERROR] Retrying in 1 second.
[2018-04-06 18:36:36 -0700] [19676] [ERROR] Invalid address: ('10.0.0.95', 22362)
[2018-04-06 18:36:36 -0700] [19676] [ERROR] Retrying in 1 second.
[2018-04-06 18:36:37 -0700] [19676] [ERROR] Invalid address: ('10.0.0.95', 22362)
[2018-04-06 18:36:37 -0700] [19676] [ERROR] Retrying in 1 second.
[2018-04-06 18:36:38 -0700] [19676] [ERROR] Invalid address: ('10.0.0.95', 22362)
[2018-04-06 18:36:38 -0700] [19676] [ERROR] Retrying in 1 second.
[2018-04-06 18:36:39 -0700] [19676] [ERROR] Invalid address: ('10.0.0.95', 22362)
[2018-04-06 18:36:39 -0700] [19676] [ERROR] Retrying in 1 second.
[2018-04-06 18:36:40 -0700] [19676] [ERROR] Can't connect to ('10.0.0.95', 22362)
[2018-04-06 18:41:39 -0700] [19732] [ERROR] Invalid address: ('10.0.0.95', 22362)
[2018-04-06 18:41:39 -0700] [19732] [ERROR] Retrying in 1 second.
[2018-04-06 18:41:40 -0700] [19732] [ERROR] Invalid address: ('10.0.0.95', 22362)
[2018-04-06 18:41:40 -0700] [19732] [ERROR] Retrying in 1 second.
[2018-04-06 18:41:41 -0700] [19732] [ERROR] Invalid address: ('10.0.0.95', 22362)
[2018-04-06 18:41:41 -0700] [19732] [ERROR] Retrying in 1 second.
[2018-04-06 18:41:42 -0700] [19732] [ERROR] Invalid address: ('10.0.0.95', 22362)
[2018-04-06 18:41:42 -0700] [19732] [ERROR] Retrying in 1 second.
[2018-04-06 18:41:43 -0700] [19732] [ERROR] Invalid address: ('10.0.0.95', 22362)
[2018-04-06 18:41:43 -0700] [19732] [ERROR] Retrying in 1 second.
[2018-04-06 18:41:44 -0700] [19732] [ERROR] Can't connect to ('10.0.0.95', 22362)
[2018-04-06 18:46:17 -0700] [20211] [ERROR] Invalid address: ('10.0.0.95', 22362)
[2018-04-06 18:46:17 -0700] [20211] [ERROR] Retrying in 1 second.
[2018-04-06 18:46:18 -0700] [20211] [ERROR] Invalid address: ('10.0.0.95', 22362)
[2018-04-06 18:46:18 -0700] [20211] [ERROR] Retrying in 1 second.
[2018-04-06 18:46:19 -0700] [20211] [ERROR] Invalid address: ('10.0.0.95', 22362)
[2018-04-06 18:46:19 -0700] [20211] [ERROR] Retrying in 1 second.
[2018-04-06 18:46:20 -0700] [20211] [ERROR] Invalid address: ('10.0.0.95', 22362)
[2018-04-06 18:46:20 -0700] [20211] [ERROR] Retrying in 1 second.
[2018-04-06 18:46:21 -0700] [20211] [ERROR] Invalid address: ('10.0.0.95', 22362)
[2018-04-06 18:46:21 -0700] [20211] [ERROR] Retrying in 1 second.
[2018-04-06 18:46:22 -0700] [20211] [ERROR] Can't connect to ('10.0.0.95', 22362)
[2018-04-06 18:46:35 -0700] [20229] [ERROR] Invalid address: ('10.0.0.95', 5000)
[2018-04-06 18:46:35 -0700] [20229] [ERROR] Retrying in 1 second.
[2018-04-06 18:46:36 -0700] [20229] [ERROR] Invalid address: ('10.0.0.95', 5000)
[2018-04-06 18:46:36 -0700] [20229] [ERROR] Retrying in 1 second.
[2018-04-06 18:46:37 -0700] [20229] [ERROR] Invalid address: ('10.0.0.95', 5000)
[2018-04-06 18:46:37 -0700] [20229] [ERROR] Retrying in 1 second.
[2018-04-06 18:46:38 -0700] [20229] [ERROR] Invalid address: ('10.0.0.95', 5000)
[2018-04-06 18:46:38 -0700] [20229] [ERROR] Retrying in 1 second.
[2018-04-06 18:46:39 -0700] [20229] [ERROR] Invalid address: ('10.0.0.95', 5000)
[2018-04-06 18:46:39 -0700] [20229] [ERROR] Retrying in 1 second.
[2018-04-06 18:46:40 -0700] [20229] [ERROR] Can't connect to ('10.0.0.95', 5000)
[2018-04-06 18:47:55 -0700] [20382] [ERROR] Invalid address: ('10.0.0.95', 22362)
[2018-04-06 18:47:55 -0700] [20382] [ERROR] Retrying in 1 second.
[2018-04-06 18:47:56 -0700] [20382] [ERROR] Invalid address: ('10.0.0.95', 22362)
[2018-04-06 18:47:56 -0700] [20382] [ERROR] Retrying in 1 second.
[2018-04-06 18:47:57 -0700] [20382] [ERROR] Invalid address: ('10.0.0.95', 22362)
[2018-04-06 18:47:57 -0700] [20382] [ERROR] Retrying in 1 second.
[2018-04-06 18:47:58 -0700] [20382] [ERROR] Invalid address: ('10.0.0.95', 22362)
[2018-04-06 18:47:58 -0700] [20382] [ERROR] Retrying in 1 second.
[2018-04-06 18:47:59 -0700] [20382] [ERROR] Invalid address: ('10.0.0.95', 22362)
[2018-04-06 18:47:59 -0700] [20382] [ERROR] Retrying in 1 second.
[2018-04-06 18:48:00 -0700] [20382] [ERROR] Can't connect to ('10.0.0.95', 22362)
[2018-04-06 18:48:48 -0700] [20409] [ERROR] Invalid address: ('10.0.0.95', 22362)
[2018-04-06 18:48:48 -0700] [20409] [ERROR] Retrying in 1 second.
[2018-04-06 18:48:49 -0700] [20409] [ERROR] Invalid address: ('10.0.0.95', 22362)
[2018-04-06 18:48:49 -0700] [20409] [ERROR] Retrying in 1 second.
[2018-04-06 18:48:50 -0700] [20409] [ERROR] Invalid address: ('10.0.0.95', 22362)
[2018-04-06 18:48:50 -0700] [20409] [ERROR] Retrying in 1 second.
[2018-04-06 18:48:51 -0700] [20409] [ERROR] Invalid address: ('10.0.0.95', 22362)
[2018-04-06 18:48:51 -0700] [20409] [ERROR] Retrying in 1 second.
[2018-04-06 18:48:52 -0700] [20409] [ERROR] Invalid address: ('10.0.0.95', 22362)
[2018-04-06 18:48:52 -0700] [20409] [ERROR] Retrying in 1 second.
[2018-04-06 18:48:53 -0700] [20409] [ERROR] Can't connect to ('10.0.0.95', 22362)
[2018-04-06 18:52:31 -0700] [20456] [ERROR] Invalid address: ('10.0.0.95', 22362)
[2018-04-06 18:52:31 -0700] [20456] [ERROR] Retrying in 1 second.
[2018-04-06 18:52:32 -0700] [20456] [ERROR] Invalid address: ('10.0.0.95', 22362)
[2018-04-06 18:52:32 -0700] [20456] [ERROR] Retrying in 1 second.
[2018-04-06 18:52:33 -0700] [20456] [ERROR] Invalid address: ('10.0.0.95', 22362)
[2018-04-06 18:52:33 -0700] [20456] [ERROR] Retrying in 1 second.
[2018-04-06 18:52:34 -0700] [20456] [ERROR] Invalid address: ('10.0.0.95', 22362)
[2018-04-06 18:52:34 -0700] [20456] [ERROR] Retrying in 1 second.
[2018-04-06 18:52:35 -0700] [20456] [ERROR] Invalid address: ('10.0.0.95', 22362)
[2018-04-06 18:52:35 -0700] [20456] [ERROR] Retrying in 1 second.
[2018-04-06 18:52:36 -0700] [20456] [ERROR] Can't connect to ('10.0.0.95', 22362)
[2018-04-06 19:33:43 -0700] [20248] [CRITICAL] WORKER TIMEOUT (pid:20332)
[2018-04-06 19:33:43 -0700] [20248] [CRITICAL] WORKER TIMEOUT (pid:20333)
[2018-04-06 19:33:43 -0700] [20248] [CRITICAL] WORKER TIMEOUT (pid:20334)
[2018-04-06 19:33:43 -0700] [20248] [CRITICAL] WORKER TIMEOUT (pid:20337)
[2018-04-06 19:33:43 -0700] [20248] [CRITICAL] WORKER TIMEOUT (pid:20338)
[2018-04-06 19:33:43 -0700] [20248] [CRITICAL] WORKER TIMEOUT (pid:20339)
[2018-04-06 19:33:43 -0700] [20248] [CRITICAL] WORKER TIMEOUT (pid:20340)
[2018-04-06 19:33:43 -0700] [20248] [CRITICAL] WORKER TIMEOUT (pid:20342)
[2018-04-06 19:33:43 -0700] [20248] [CRITICAL] WORKER TIMEOUT (pid:20344)
[2018-04-06 19:33:43 -0700] [20474] [CRITICAL] WORKER TIMEOUT (pid:20535)
[2018-04-06 19:33:43 -0700] [20474] [CRITICAL] WORKER TIMEOUT (pid:20536)
[2018-04-06 19:33:43 -0700] [20474] [CRITICAL] WORKER TIMEOUT (pid:20537)
[2018-04-06 19:33:43 -0700] [20474] [CRITICAL] WORKER TIMEOUT (pid:20538)
[2018-04-06 19:33:43 -0700] [20474] [CRITICAL] WORKER TIMEOUT (pid:20539)
[2018-04-06 19:33:43 -0700] [20474] [CRITICAL] WORKER TIMEOUT (pid:20540)
[2018-04-06 19:33:43 -0700] [20474] [CRITICAL] WORKER TIMEOUT (pid:20541)
[2018-04-06 19:33:43 -0700] [20474] [CRITICAL] WORKER TIMEOUT (pid:20542)
[2018-04-06 19:33:43 -0700] [20474] [CRITICAL] WORKER TIMEOUT (pid:20543)
[2018-04-09 14:41:57 -0700] [3230] [ERROR] Invalid address: ('10.0.0.95', 22362)
[2018-04-09 14:41:57 -0700] [3230] [ERROR] Retrying in 1 second.
[2018-04-09 14:41:58 -0700] [3230] [ERROR] Invalid address: ('10.0.0.95', 22362)
[2018-04-09 14:41:58 -0700] [3230] [ERROR] Retrying in 1 second.
[2018-04-09 14:41:59 -0700] [3230] [ERROR] Invalid address: ('10.0.0.95', 22362)
[2018-04-09 14:41:59 -0700] [3230] [ERROR] Retrying in 1 second.
[2018-04-09 14:42:00 -0700] [3230] [ERROR] Invalid address: ('10.0.0.95', 22362)
[2018-04-09 14:42:00 -0700] [3230] [ERROR] Retrying in 1 second.
[2018-04-09 14:42:01 -0700] [3230] [ERROR] Invalid address: ('10.0.0.95', 22362)
[2018-04-09 14:42:01 -0700] [3230] [ERROR] Retrying in 1 second.
[2018-04-09 14:42:02 -0700] [3230] [ERROR] Can't connect to ('10.0.0.95', 22362)
[2018-04-09 17:34:58 -0700] [3504] [CRITICAL] WORKER TIMEOUT (pid:3587)
[2018-04-09 17:34:58 -0700] [3504] [CRITICAL] WORKER TIMEOUT (pid:3588)
[2018-04-09 17:34:58 -0700] [3504] [CRITICAL] WORKER TIMEOUT (pid:3589)
[2018-04-09 17:34:58 -0700] [3504] [CRITICAL] WORKER TIMEOUT (pid:3591)
[2018-04-09 17:34:58 -0700] [3504] [CRITICAL] WORKER TIMEOUT (pid:3593)
[2018-04-09 17:34:58 -0700] [3504] [CRITICAL] WORKER TIMEOUT (pid:3594)
[2018-04-09 17:34:58 -0700] [3504] [CRITICAL] WORKER TIMEOUT (pid:3595)
[2018-04-09 17:34:58 -0700] [3504] [CRITICAL] WORKER TIMEOUT (pid:3597)
[2018-04-09 17:34:58 -0700] [3504] [CRITICAL] WORKER TIMEOUT (pid:3599)
[2018-04-09 18:45:06 -0700] [3504] [CRITICAL] WORKER TIMEOUT (pid:5726)
[2018-04-09 20:36:43 +0000] [19210] [ERROR] Connection in use: ('0.0.0.0', 22362)
[2018-04-09 20:36:43 +0000] [19210] [ERROR] Retrying in 1 second.
[2018-04-09 20:36:44 +0000] [19210] [ERROR] Connection in use: ('0.0.0.0', 22362)
[2018-04-09 20:36:44 +0000] [19210] [ERROR] Retrying in 1 second.
[2018-04-09 20:36:45 +0000] [19210] [ERROR] Connection in use: ('0.0.0.0', 22362)
[2018-04-09 20:36:45 +0000] [19210] [ERROR] Retrying in 1 second.
[2018-04-09 20:36:46 +0000] [19210] [ERROR] Connection in use: ('0.0.0.0', 22362)
[2018-04-09 20:36:46 +0000] [19210] [ERROR] Retrying in 1 second.
[2018-04-09 20:36:47 +0000] [19210] [ERROR] Connection in use: ('0.0.0.0', 22362)
[2018-04-09 20:36:47 +0000] [19210] [ERROR] Retrying in 1 second.
[2018-04-09 20:36:48 +0000] [19210] [ERROR] Can't connect to ('0.0.0.0', 22362)
